[2022-12-14 04:33:43,618] {taskinstance.py:1032} INFO - Dependencies all met for <TaskInstance: data_ingestion_tripdata1_dag.local_to_gcs_task scheduled__2022-12-13T00:00:00+00:00 [queued]>
[2022-12-14 04:33:43,637] {taskinstance.py:1032} INFO - Dependencies all met for <TaskInstance: data_ingestion_tripdata1_dag.local_to_gcs_task scheduled__2022-12-13T00:00:00+00:00 [queued]>
[2022-12-14 04:33:43,638] {taskinstance.py:1238} INFO - 
--------------------------------------------------------------------------------
[2022-12-14 04:33:43,638] {taskinstance.py:1239} INFO - Starting attempt 5 of 5
[2022-12-14 04:33:43,638] {taskinstance.py:1240} INFO - 
--------------------------------------------------------------------------------
[2022-12-14 04:33:43,658] {taskinstance.py:1259} INFO - Executing <Task(PythonOperator): local_to_gcs_task> on 2022-12-13 00:00:00+00:00
[2022-12-14 04:33:43,668] {standard_task_runner.py:52} INFO - Started process 339 to run task
[2022-12-14 04:33:43,677] {standard_task_runner.py:76} INFO - Running: ['***', 'tasks', 'run', 'data_ingestion_tripdata1_dag', 'local_to_gcs_task', 'scheduled__2022-12-13T00:00:00+00:00', '--job-id', '218', '--raw', '--subdir', 'DAGS_FOLDER/data_ingestion_tripdata1_dag.py', '--cfg-path', '/tmp/tmplcxgeoe2', '--error-file', '/tmp/tmpu5sjtn_5']
[2022-12-14 04:33:43,679] {standard_task_runner.py:77} INFO - Job 218: Subtask local_to_gcs_task
[2022-12-14 04:33:43,771] {logging_mixin.py:109} INFO - Running <TaskInstance: data_ingestion_tripdata1_dag.local_to_gcs_task scheduled__2022-12-13T00:00:00+00:00 [running]> on host 3aa8f9c0af4f
[2022-12-14 04:33:43,882] {taskinstance.py:1426} INFO - Exporting the following env vars:
AIRFLOW_CTX_DAG_OWNER=***
AIRFLOW_CTX_DAG_ID=data_ingestion_tripdata1_dag
AIRFLOW_CTX_TASK_ID=local_to_gcs_task
AIRFLOW_CTX_EXECUTION_DATE=2022-12-13T00:00:00+00:00
AIRFLOW_CTX_DAG_RUN_ID=scheduled__2022-12-13T00:00:00+00:00
[2022-12-14 04:33:43,907] {taskinstance.py:1700} ERROR - Task failed with exception
Traceback (most recent call last):
  File "/home/airflow/.local/lib/python3.7/site-packages/airflow/models/taskinstance.py", line 1329, in _run_raw_task
    self._execute_task_with_callbacks(context)
  File "/home/airflow/.local/lib/python3.7/site-packages/airflow/models/taskinstance.py", line 1455, in _execute_task_with_callbacks
    result = self._execute_task(context, self.task)
  File "/home/airflow/.local/lib/python3.7/site-packages/airflow/models/taskinstance.py", line 1511, in _execute_task
    result = execute_callable(context=context)
  File "/home/airflow/.local/lib/python3.7/site-packages/airflow/operators/python.py", line 174, in execute
    return_value = self.execute_callable()
  File "/home/airflow/.local/lib/python3.7/site-packages/airflow/operators/python.py", line 185, in execute_callable
    return self.python_callable(*self.op_args, **self.op_kwargs)
  File "/opt/airflow/dags/data_ingestion_tripdata1_dag.py", line 60, in upload_to_gcs
    blob.upload_from_filename(local_file)
  File "/home/airflow/.local/lib/python3.7/site-packages/google/cloud/storage/blob.py", line 2720, in upload_from_filename
    with open(filename, "rb") as file_obj:
FileNotFoundError: [Errno 2] No such file or directory: '/opt/airflow/part-00006-64ea0de6-d39a-42f0-9ba5-2200d99d66d6-c000.snappy.parquet'
[2022-12-14 04:33:43,931] {taskinstance.py:1277} INFO - Marking task as FAILED. dag_id=data_ingestion_tripdata1_dag, task_id=local_to_gcs_task, execution_date=20221213T000000, start_date=20221214T043343, end_date=20221214T043343
[2022-12-14 04:33:43,966] {standard_task_runner.py:92} ERROR - Failed to execute job 218 for task local_to_gcs_task
Traceback (most recent call last):
  File "/home/airflow/.local/lib/python3.7/site-packages/airflow/task/task_runner/standard_task_runner.py", line 85, in _start_by_fork
    args.func(args, dag=self.dag)
  File "/home/airflow/.local/lib/python3.7/site-packages/airflow/cli/cli_parser.py", line 48, in command
    return func(*args, **kwargs)
  File "/home/airflow/.local/lib/python3.7/site-packages/airflow/utils/cli.py", line 92, in wrapper
    return f(*args, **kwargs)
  File "/home/airflow/.local/lib/python3.7/site-packages/airflow/cli/commands/task_command.py", line 298, in task_run
    _run_task_by_selected_method(args, dag, ti)
  File "/home/airflow/.local/lib/python3.7/site-packages/airflow/cli/commands/task_command.py", line 107, in _run_task_by_selected_method
    _run_raw_task(args, ti)
  File "/home/airflow/.local/lib/python3.7/site-packages/airflow/cli/commands/task_command.py", line 184, in _run_raw_task
    error_file=args.error_file,
  File "/home/airflow/.local/lib/python3.7/site-packages/airflow/utils/session.py", line 70, in wrapper
    return func(*args, session=session, **kwargs)
  File "/home/airflow/.local/lib/python3.7/site-packages/airflow/models/taskinstance.py", line 1329, in _run_raw_task
    self._execute_task_with_callbacks(context)
  File "/home/airflow/.local/lib/python3.7/site-packages/airflow/models/taskinstance.py", line 1455, in _execute_task_with_callbacks
    result = self._execute_task(context, self.task)
  File "/home/airflow/.local/lib/python3.7/site-packages/airflow/models/taskinstance.py", line 1511, in _execute_task
    result = execute_callable(context=context)
  File "/home/airflow/.local/lib/python3.7/site-packages/airflow/operators/python.py", line 174, in execute
    return_value = self.execute_callable()
  File "/home/airflow/.local/lib/python3.7/site-packages/airflow/operators/python.py", line 185, in execute_callable
    return self.python_callable(*self.op_args, **self.op_kwargs)
  File "/opt/airflow/dags/data_ingestion_tripdata1_dag.py", line 60, in upload_to_gcs
    blob.upload_from_filename(local_file)
  File "/home/airflow/.local/lib/python3.7/site-packages/google/cloud/storage/blob.py", line 2720, in upload_from_filename
    with open(filename, "rb") as file_obj:
FileNotFoundError: [Errno 2] No such file or directory: '/opt/airflow/part-00006-64ea0de6-d39a-42f0-9ba5-2200d99d66d6-c000.snappy.parquet'
[2022-12-14 04:33:44,017] {local_task_job.py:154} INFO - Task exited with return code 1
[2022-12-14 04:33:44,161] {dagrun.py:628} WARNING - Failed to get task '<TaskInstance: data_ingestion_tripdata1_dag.download_dataset_task scheduled__2022-12-13T00:00:00+00:00 [removed]>' for dag 'data_ingestion_tripdata1_dag'. Marking it as removed.
[2022-12-14 04:33:44,172] {local_task_job.py:264} INFO - 0 downstream tasks scheduled from follow-on schedule check
