[2022-12-05 07:33:57,054] {taskinstance.py:1032} INFO - Dependencies all met for <TaskInstance: data_ingestion_gcs_dag.local_to_gcs_task scheduled__2022-12-04T00:00:00+00:00 [queued]>
[2022-12-05 07:33:57,075] {taskinstance.py:1032} INFO - Dependencies all met for <TaskInstance: data_ingestion_gcs_dag.local_to_gcs_task scheduled__2022-12-04T00:00:00+00:00 [queued]>
[2022-12-05 07:33:57,075] {taskinstance.py:1238} INFO - 
--------------------------------------------------------------------------------
[2022-12-05 07:33:57,075] {taskinstance.py:1239} INFO - Starting attempt 1 of 2
[2022-12-05 07:33:57,075] {taskinstance.py:1240} INFO - 
--------------------------------------------------------------------------------
[2022-12-05 07:33:57,100] {taskinstance.py:1259} INFO - Executing <Task(PythonOperator): local_to_gcs_task> on 2022-12-04 00:00:00+00:00
[2022-12-05 07:33:57,110] {standard_task_runner.py:52} INFO - Started process 175 to run task
[2022-12-05 07:33:57,123] {standard_task_runner.py:76} INFO - Running: ['***', 'tasks', 'run', 'data_ingestion_gcs_dag', 'local_to_gcs_task', 'scheduled__2022-12-04T00:00:00+00:00', '--job-id', '118', '--raw', '--subdir', 'DAGS_FOLDER/data_ingestion_gcs_dag.py', '--cfg-path', '/tmp/tmpn9_zvkwa', '--error-file', '/tmp/tmpwgcgtbgh']
[2022-12-05 07:33:57,124] {standard_task_runner.py:77} INFO - Job 118: Subtask local_to_gcs_task
[2022-12-05 07:33:57,227] {logging_mixin.py:109} INFO - Running <TaskInstance: data_ingestion_gcs_dag.local_to_gcs_task scheduled__2022-12-04T00:00:00+00:00 [running]> on host 6efb45a5158d
[2022-12-05 07:33:57,364] {taskinstance.py:1426} INFO - Exporting the following env vars:
AIRFLOW_CTX_DAG_OWNER=***
AIRFLOW_CTX_DAG_ID=data_ingestion_gcs_dag
AIRFLOW_CTX_TASK_ID=local_to_gcs_task
AIRFLOW_CTX_EXECUTION_DATE=2022-12-04T00:00:00+00:00
AIRFLOW_CTX_DAG_RUN_ID=scheduled__2022-12-04T00:00:00+00:00
[2022-12-05 07:33:57,397] {taskinstance.py:1700} ERROR - Task failed with exception
Traceback (most recent call last):
  File "/home/airflow/.local/lib/python3.7/site-packages/airflow/models/taskinstance.py", line 1329, in _run_raw_task
    self._execute_task_with_callbacks(context)
  File "/home/airflow/.local/lib/python3.7/site-packages/airflow/models/taskinstance.py", line 1455, in _execute_task_with_callbacks
    result = self._execute_task(context, self.task)
  File "/home/airflow/.local/lib/python3.7/site-packages/airflow/models/taskinstance.py", line 1511, in _execute_task
    result = execute_callable(context=context)
  File "/home/airflow/.local/lib/python3.7/site-packages/airflow/operators/python.py", line 174, in execute
    return_value = self.execute_callable()
  File "/home/airflow/.local/lib/python3.7/site-packages/airflow/operators/python.py", line 185, in execute_callable
    return self.python_callable(*self.op_args, **self.op_kwargs)
  File "/opt/airflow/dags/data_ingestion_gcs_dag.py", line 86, in upload_to_gcs
    blob.upload_from_filename(local_file)
  File "/home/airflow/.local/lib/python3.7/site-packages/google/cloud/storage/blob.py", line 2720, in upload_from_filename
    with open(filename, "rb") as file_obj:
FileNotFoundError: [Errno 2] No such file or directory: '/opt/airflow/Nation_Population.json'
[2022-12-05 07:33:57,431] {taskinstance.py:1277} INFO - Marking task as UP_FOR_RETRY. dag_id=data_ingestion_gcs_dag, task_id=local_to_gcs_task, execution_date=20221204T000000, start_date=20221205T073357, end_date=20221205T073357
[2022-12-05 07:33:57,458] {standard_task_runner.py:92} ERROR - Failed to execute job 118 for task local_to_gcs_task
Traceback (most recent call last):
  File "/home/airflow/.local/lib/python3.7/site-packages/airflow/task/task_runner/standard_task_runner.py", line 85, in _start_by_fork
    args.func(args, dag=self.dag)
  File "/home/airflow/.local/lib/python3.7/site-packages/airflow/cli/cli_parser.py", line 48, in command
    return func(*args, **kwargs)
  File "/home/airflow/.local/lib/python3.7/site-packages/airflow/utils/cli.py", line 92, in wrapper
    return f(*args, **kwargs)
  File "/home/airflow/.local/lib/python3.7/site-packages/airflow/cli/commands/task_command.py", line 298, in task_run
    _run_task_by_selected_method(args, dag, ti)
  File "/home/airflow/.local/lib/python3.7/site-packages/airflow/cli/commands/task_command.py", line 107, in _run_task_by_selected_method
    _run_raw_task(args, ti)
  File "/home/airflow/.local/lib/python3.7/site-packages/airflow/cli/commands/task_command.py", line 184, in _run_raw_task
    error_file=args.error_file,
  File "/home/airflow/.local/lib/python3.7/site-packages/airflow/utils/session.py", line 70, in wrapper
    return func(*args, session=session, **kwargs)
  File "/home/airflow/.local/lib/python3.7/site-packages/airflow/models/taskinstance.py", line 1329, in _run_raw_task
    self._execute_task_with_callbacks(context)
  File "/home/airflow/.local/lib/python3.7/site-packages/airflow/models/taskinstance.py", line 1455, in _execute_task_with_callbacks
    result = self._execute_task(context, self.task)
  File "/home/airflow/.local/lib/python3.7/site-packages/airflow/models/taskinstance.py", line 1511, in _execute_task
    result = execute_callable(context=context)
  File "/home/airflow/.local/lib/python3.7/site-packages/airflow/operators/python.py", line 174, in execute
    return_value = self.execute_callable()
  File "/home/airflow/.local/lib/python3.7/site-packages/airflow/operators/python.py", line 185, in execute_callable
    return self.python_callable(*self.op_args, **self.op_kwargs)
  File "/opt/airflow/dags/data_ingestion_gcs_dag.py", line 86, in upload_to_gcs
    blob.upload_from_filename(local_file)
  File "/home/airflow/.local/lib/python3.7/site-packages/google/cloud/storage/blob.py", line 2720, in upload_from_filename
    with open(filename, "rb") as file_obj:
FileNotFoundError: [Errno 2] No such file or directory: '/opt/airflow/Nation_Population.json'
[2022-12-05 07:33:57,504] {local_task_job.py:154} INFO - Task exited with return code 1
[2022-12-05 07:33:57,577] {local_task_job.py:264} INFO - 0 downstream tasks scheduled from follow-on schedule check
[2022-12-05 11:40:00,852] {taskinstance.py:1032} INFO - Dependencies all met for <TaskInstance: data_ingestion_gcs_dag.local_to_gcs_task scheduled__2022-12-04T00:00:00+00:00 [queued]>
[2022-12-05 11:40:00,872] {taskinstance.py:1032} INFO - Dependencies all met for <TaskInstance: data_ingestion_gcs_dag.local_to_gcs_task scheduled__2022-12-04T00:00:00+00:00 [queued]>
[2022-12-05 11:40:00,873] {taskinstance.py:1238} INFO - 
--------------------------------------------------------------------------------
[2022-12-05 11:40:00,873] {taskinstance.py:1239} INFO - Starting attempt 1 of 2
[2022-12-05 11:40:00,873] {taskinstance.py:1240} INFO - 
--------------------------------------------------------------------------------
[2022-12-05 11:40:00,911] {taskinstance.py:1259} INFO - Executing <Task(PythonOperator): local_to_gcs_task> on 2022-12-04 00:00:00+00:00
[2022-12-05 11:40:00,923] {standard_task_runner.py:52} INFO - Started process 181 to run task
[2022-12-05 11:40:00,954] {standard_task_runner.py:76} INFO - Running: ['***', 'tasks', 'run', 'data_ingestion_gcs_dag', 'local_to_gcs_task', 'scheduled__2022-12-04T00:00:00+00:00', '--job-id', '16', '--raw', '--subdir', 'DAGS_FOLDER/data_ingestion_gcs_dag.py', '--cfg-path', '/tmp/tmpp2eh7t4m', '--error-file', '/tmp/tmp_16rrh_9']
[2022-12-05 11:40:00,958] {standard_task_runner.py:77} INFO - Job 16: Subtask local_to_gcs_task
[2022-12-05 11:40:01,114] {logging_mixin.py:109} INFO - Running <TaskInstance: data_ingestion_gcs_dag.local_to_gcs_task scheduled__2022-12-04T00:00:00+00:00 [running]> on host 2bdf78053424
[2022-12-05 11:40:01,231] {taskinstance.py:1426} INFO - Exporting the following env vars:
AIRFLOW_CTX_DAG_OWNER=***
AIRFLOW_CTX_DAG_ID=data_ingestion_gcs_dag
AIRFLOW_CTX_TASK_ID=local_to_gcs_task
AIRFLOW_CTX_EXECUTION_DATE=2022-12-04T00:00:00+00:00
AIRFLOW_CTX_DAG_RUN_ID=scheduled__2022-12-04T00:00:00+00:00
[2022-12-05 11:40:01,527] {python.py:175} INFO - Done. Returned value was: None
[2022-12-05 11:40:01,561] {taskinstance.py:1277} INFO - Marking task as SUCCESS. dag_id=data_ingestion_gcs_dag, task_id=local_to_gcs_task, execution_date=20221204T000000, start_date=20221205T114000, end_date=20221205T114001
[2022-12-05 11:40:01,625] {local_task_job.py:154} INFO - Task exited with return code 0
[2022-12-05 11:40:01,724] {local_task_job.py:264} INFO - 1 downstream tasks scheduled from follow-on schedule check
