[2022-12-13 06:40:49,243] {taskinstance.py:1032} INFO - Dependencies all met for <TaskInstance: data_ingestion_tripdata1_dag.local_to_gcs_task manual__2022-12-12T15:20:27.855458+00:00 [queued]>
[2022-12-13 06:40:49,267] {taskinstance.py:1032} INFO - Dependencies all met for <TaskInstance: data_ingestion_tripdata1_dag.local_to_gcs_task manual__2022-12-12T15:20:27.855458+00:00 [queued]>
[2022-12-13 06:40:49,267] {taskinstance.py:1238} INFO - 
--------------------------------------------------------------------------------
[2022-12-13 06:40:49,267] {taskinstance.py:1239} INFO - Starting attempt 5 of 6
[2022-12-13 06:40:49,267] {taskinstance.py:1240} INFO - 
--------------------------------------------------------------------------------
[2022-12-13 06:40:49,299] {taskinstance.py:1259} INFO - Executing <Task(PythonOperator): local_to_gcs_task> on 2022-12-12 15:20:27.855458+00:00
[2022-12-13 06:40:49,313] {standard_task_runner.py:52} INFO - Started process 681 to run task
[2022-12-13 06:40:49,330] {standard_task_runner.py:76} INFO - Running: ['***', 'tasks', 'run', 'data_ingestion_tripdata1_dag', 'local_to_gcs_task', 'manual__2022-12-12T15:20:27.855458+00:00', '--job-id', '155', '--raw', '--subdir', 'DAGS_FOLDER/data_ingestion_tripdata1_dag.py', '--cfg-path', '/tmp/tmph4i8gtob', '--error-file', '/tmp/tmpytwkyd1m']
[2022-12-13 06:40:49,332] {standard_task_runner.py:77} INFO - Job 155: Subtask local_to_gcs_task
[2022-12-13 06:40:49,453] {logging_mixin.py:109} INFO - Running <TaskInstance: data_ingestion_tripdata1_dag.local_to_gcs_task manual__2022-12-12T15:20:27.855458+00:00 [running]> on host c90fde5b5e35
[2022-12-13 06:40:49,616] {taskinstance.py:1426} INFO - Exporting the following env vars:
AIRFLOW_CTX_DAG_OWNER=***
AIRFLOW_CTX_DAG_ID=data_ingestion_tripdata1_dag
AIRFLOW_CTX_TASK_ID=local_to_gcs_task
AIRFLOW_CTX_EXECUTION_DATE=2022-12-12T15:20:27.855458+00:00
AIRFLOW_CTX_DAG_RUN_ID=manual__2022-12-12T15:20:27.855458+00:00
[2022-12-13 06:40:49,660] {taskinstance.py:1700} ERROR - Task failed with exception
Traceback (most recent call last):
  File "/home/airflow/.local/lib/python3.7/site-packages/airflow/models/taskinstance.py", line 1329, in _run_raw_task
    self._execute_task_with_callbacks(context)
  File "/home/airflow/.local/lib/python3.7/site-packages/airflow/models/taskinstance.py", line 1455, in _execute_task_with_callbacks
    result = self._execute_task(context, self.task)
  File "/home/airflow/.local/lib/python3.7/site-packages/airflow/models/taskinstance.py", line 1511, in _execute_task
    result = execute_callable(context=context)
  File "/home/airflow/.local/lib/python3.7/site-packages/airflow/operators/python.py", line 174, in execute
    return_value = self.execute_callable()
  File "/home/airflow/.local/lib/python3.7/site-packages/airflow/operators/python.py", line 185, in execute_callable
    return self.python_callable(*self.op_args, **self.op_kwargs)
  File "/opt/airflow/dags/data_ingestion_tripdata1_dag.py", line 53, in upload_to_gcs
    blob.upload_from_filename(local_file)
  File "/home/airflow/.local/lib/python3.7/site-packages/google/cloud/storage/blob.py", line 2720, in upload_from_filename
    with open(filename, "rb") as file_obj:
FileNotFoundError: [Errno 2] No such file or directory: '/home/rsa-key-20221208/dags/tripdata1.parquet/part-00006-64ea0de6-d39a-42f0-9ba5-2200d99d66d6-c000.snappy.parquet'
[2022-12-13 06:40:49,705] {taskinstance.py:1277} INFO - Marking task as UP_FOR_RETRY. dag_id=data_ingestion_tripdata1_dag, task_id=local_to_gcs_task, execution_date=20221212T152027, start_date=20221213T064049, end_date=20221213T064049
[2022-12-13 06:40:49,766] {standard_task_runner.py:92} ERROR - Failed to execute job 155 for task local_to_gcs_task
Traceback (most recent call last):
  File "/home/airflow/.local/lib/python3.7/site-packages/airflow/task/task_runner/standard_task_runner.py", line 85, in _start_by_fork
    args.func(args, dag=self.dag)
  File "/home/airflow/.local/lib/python3.7/site-packages/airflow/cli/cli_parser.py", line 48, in command
    return func(*args, **kwargs)
  File "/home/airflow/.local/lib/python3.7/site-packages/airflow/utils/cli.py", line 92, in wrapper
    return f(*args, **kwargs)
  File "/home/airflow/.local/lib/python3.7/site-packages/airflow/cli/commands/task_command.py", line 298, in task_run
    _run_task_by_selected_method(args, dag, ti)
  File "/home/airflow/.local/lib/python3.7/site-packages/airflow/cli/commands/task_command.py", line 107, in _run_task_by_selected_method
    _run_raw_task(args, ti)
  File "/home/airflow/.local/lib/python3.7/site-packages/airflow/cli/commands/task_command.py", line 184, in _run_raw_task
    error_file=args.error_file,
  File "/home/airflow/.local/lib/python3.7/site-packages/airflow/utils/session.py", line 70, in wrapper
    return func(*args, session=session, **kwargs)
  File "/home/airflow/.local/lib/python3.7/site-packages/airflow/models/taskinstance.py", line 1329, in _run_raw_task
    self._execute_task_with_callbacks(context)
  File "/home/airflow/.local/lib/python3.7/site-packages/airflow/models/taskinstance.py", line 1455, in _execute_task_with_callbacks
    result = self._execute_task(context, self.task)
  File "/home/airflow/.local/lib/python3.7/site-packages/airflow/models/taskinstance.py", line 1511, in _execute_task
    result = execute_callable(context=context)
  File "/home/airflow/.local/lib/python3.7/site-packages/airflow/operators/python.py", line 174, in execute
    return_value = self.execute_callable()
  File "/home/airflow/.local/lib/python3.7/site-packages/airflow/operators/python.py", line 185, in execute_callable
    return self.python_callable(*self.op_args, **self.op_kwargs)
  File "/opt/airflow/dags/data_ingestion_tripdata1_dag.py", line 53, in upload_to_gcs
    blob.upload_from_filename(local_file)
  File "/home/airflow/.local/lib/python3.7/site-packages/google/cloud/storage/blob.py", line 2720, in upload_from_filename
    with open(filename, "rb") as file_obj:
FileNotFoundError: [Errno 2] No such file or directory: '/home/rsa-key-20221208/dags/tripdata1.parquet/part-00006-64ea0de6-d39a-42f0-9ba5-2200d99d66d6-c000.snappy.parquet'
[2022-12-13 06:40:49,847] {local_task_job.py:154} INFO - Task exited with return code 1
[2022-12-13 06:40:49,960] {local_task_job.py:264} INFO - 0 downstream tasks scheduled from follow-on schedule check
