[2022-12-05 05:18:52,483] {taskinstance.py:1032} INFO - Dependencies all met for <TaskInstance: data_ingestion_gcs_dag.getData scheduled__2022-12-04T00:00:00+00:00 [queued]>
[2022-12-05 05:18:52,503] {taskinstance.py:1032} INFO - Dependencies all met for <TaskInstance: data_ingestion_gcs_dag.getData scheduled__2022-12-04T00:00:00+00:00 [queued]>
[2022-12-05 05:18:52,504] {taskinstance.py:1238} INFO - 
--------------------------------------------------------------------------------
[2022-12-05 05:18:52,504] {taskinstance.py:1239} INFO - Starting attempt 1 of 2
[2022-12-05 05:18:52,504] {taskinstance.py:1240} INFO - 
--------------------------------------------------------------------------------
[2022-12-05 05:18:52,529] {taskinstance.py:1259} INFO - Executing <Task(PythonOperator): getData> on 2022-12-04 00:00:00+00:00
[2022-12-05 05:18:52,553] {standard_task_runner.py:52} INFO - Started process 238 to run task
[2022-12-05 05:18:52,577] {standard_task_runner.py:76} INFO - Running: ['***', 'tasks', 'run', 'data_ingestion_gcs_dag', 'getData', 'scheduled__2022-12-04T00:00:00+00:00', '--job-id', '93', '--raw', '--subdir', 'DAGS_FOLDER/data_ingestion_gcs_dag.py', '--cfg-path', '/tmp/tmpygjqo1h9', '--error-file', '/tmp/tmpze2vbbx6']
[2022-12-05 05:18:52,579] {standard_task_runner.py:77} INFO - Job 93: Subtask getData
[2022-12-05 05:18:52,853] {logging_mixin.py:109} INFO - Running <TaskInstance: data_ingestion_gcs_dag.getData scheduled__2022-12-04T00:00:00+00:00 [running]> on host 038cafce2530
[2022-12-05 05:18:53,125] {taskinstance.py:1426} INFO - Exporting the following env vars:
AIRFLOW_CTX_DAG_OWNER=***
AIRFLOW_CTX_DAG_ID=data_ingestion_gcs_dag
AIRFLOW_CTX_TASK_ID=getData
AIRFLOW_CTX_EXECUTION_DATE=2022-12-04T00:00:00+00:00
AIRFLOW_CTX_DAG_RUN_ID=scheduled__2022-12-04T00:00:00+00:00
[2022-12-05 05:18:53,127] {taskinstance.py:1700} ERROR - Task failed with exception
Traceback (most recent call last):
  File "/home/airflow/.local/lib/python3.7/site-packages/airflow/models/taskinstance.py", line 1329, in _run_raw_task
    self._execute_task_with_callbacks(context)
  File "/home/airflow/.local/lib/python3.7/site-packages/airflow/models/taskinstance.py", line 1455, in _execute_task_with_callbacks
    result = self._execute_task(context, self.task)
  File "/home/airflow/.local/lib/python3.7/site-packages/airflow/models/taskinstance.py", line 1511, in _execute_task
    result = execute_callable(context=context)
  File "/home/airflow/.local/lib/python3.7/site-packages/airflow/operators/python.py", line 174, in execute
    return_value = self.execute_callable()
  File "/home/airflow/.local/lib/python3.7/site-packages/airflow/operators/python.py", line 185, in execute_callable
    return self.python_callable(*self.op_args, **self.op_kwargs)
TypeError: getData() missing 1 required positional argument: 'iy'
[2022-12-05 05:18:53,164] {taskinstance.py:1277} INFO - Marking task as UP_FOR_RETRY. dag_id=data_ingestion_gcs_dag, task_id=getData, execution_date=20221204T000000, start_date=20221205T051852, end_date=20221205T051853
[2022-12-05 05:18:53,228] {standard_task_runner.py:92} ERROR - Failed to execute job 93 for task getData
Traceback (most recent call last):
  File "/home/airflow/.local/lib/python3.7/site-packages/airflow/task/task_runner/standard_task_runner.py", line 85, in _start_by_fork
    args.func(args, dag=self.dag)
  File "/home/airflow/.local/lib/python3.7/site-packages/airflow/cli/cli_parser.py", line 48, in command
    return func(*args, **kwargs)
  File "/home/airflow/.local/lib/python3.7/site-packages/airflow/utils/cli.py", line 92, in wrapper
    return f(*args, **kwargs)
  File "/home/airflow/.local/lib/python3.7/site-packages/airflow/cli/commands/task_command.py", line 298, in task_run
    _run_task_by_selected_method(args, dag, ti)
  File "/home/airflow/.local/lib/python3.7/site-packages/airflow/cli/commands/task_command.py", line 107, in _run_task_by_selected_method
    _run_raw_task(args, ti)
  File "/home/airflow/.local/lib/python3.7/site-packages/airflow/cli/commands/task_command.py", line 184, in _run_raw_task
    error_file=args.error_file,
  File "/home/airflow/.local/lib/python3.7/site-packages/airflow/utils/session.py", line 70, in wrapper
    return func(*args, session=session, **kwargs)
  File "/home/airflow/.local/lib/python3.7/site-packages/airflow/models/taskinstance.py", line 1329, in _run_raw_task
    self._execute_task_with_callbacks(context)
  File "/home/airflow/.local/lib/python3.7/site-packages/airflow/models/taskinstance.py", line 1455, in _execute_task_with_callbacks
    result = self._execute_task(context, self.task)
  File "/home/airflow/.local/lib/python3.7/site-packages/airflow/models/taskinstance.py", line 1511, in _execute_task
    result = execute_callable(context=context)
  File "/home/airflow/.local/lib/python3.7/site-packages/airflow/operators/python.py", line 174, in execute
    return_value = self.execute_callable()
  File "/home/airflow/.local/lib/python3.7/site-packages/airflow/operators/python.py", line 185, in execute_callable
    return self.python_callable(*self.op_args, **self.op_kwargs)
TypeError: getData() missing 1 required positional argument: 'iy'
[2022-12-05 05:18:53,276] {local_task_job.py:154} INFO - Task exited with return code 1
[2022-12-05 05:18:53,367] {dagrun.py:628} WARNING - Failed to get task '<TaskInstance: data_ingestion_gcs_dag.get_data_task scheduled__2022-12-04T00:00:00+00:00 [removed]>' for dag 'data_ingestion_gcs_dag'. Marking it as removed.
[2022-12-05 05:18:53,397] {local_task_job.py:264} INFO - 0 downstream tasks scheduled from follow-on schedule check
[2022-12-05 11:23:01,575] {taskinstance.py:1032} INFO - Dependencies all met for <TaskInstance: data_ingestion_gcs_dag.getData scheduled__2022-12-04T00:00:00+00:00 [queued]>
[2022-12-05 11:23:01,595] {taskinstance.py:1032} INFO - Dependencies all met for <TaskInstance: data_ingestion_gcs_dag.getData scheduled__2022-12-04T00:00:00+00:00 [queued]>
[2022-12-05 11:23:01,595] {taskinstance.py:1238} INFO - 
--------------------------------------------------------------------------------
[2022-12-05 11:23:01,595] {taskinstance.py:1239} INFO - Starting attempt 1 of 2
[2022-12-05 11:23:01,595] {taskinstance.py:1240} INFO - 
--------------------------------------------------------------------------------
[2022-12-05 11:23:01,621] {taskinstance.py:1259} INFO - Executing <Task(PythonOperator): getData> on 2022-12-04 00:00:00+00:00
[2022-12-05 11:23:01,632] {standard_task_runner.py:52} INFO - Started process 165 to run task
[2022-12-05 11:23:01,641] {standard_task_runner.py:76} INFO - Running: ['***', 'tasks', 'run', 'data_ingestion_gcs_dag', 'getData', 'scheduled__2022-12-04T00:00:00+00:00', '--job-id', '3', '--raw', '--subdir', 'DAGS_FOLDER/data_ingestion_gcs_dag.py', '--cfg-path', '/tmp/tmp7ue2w6q5', '--error-file', '/tmp/tmp7rrg1w8v']
[2022-12-05 11:23:01,643] {standard_task_runner.py:77} INFO - Job 3: Subtask getData
[2022-12-05 11:23:01,749] {logging_mixin.py:109} INFO - Running <TaskInstance: data_ingestion_gcs_dag.getData scheduled__2022-12-04T00:00:00+00:00 [running]> on host 773d78d86e4f
[2022-12-05 11:23:01,906] {taskinstance.py:1426} INFO - Exporting the following env vars:
AIRFLOW_CTX_DAG_OWNER=***
AIRFLOW_CTX_DAG_ID=data_ingestion_gcs_dag
AIRFLOW_CTX_TASK_ID=getData
AIRFLOW_CTX_EXECUTION_DATE=2022-12-04T00:00:00+00:00
AIRFLOW_CTX_DAG_RUN_ID=scheduled__2022-12-04T00:00:00+00:00
[2022-12-05 11:23:02,106] {python.py:175} INFO - Done. Returned value was: None
[2022-12-05 11:23:02,139] {taskinstance.py:1277} INFO - Marking task as SUCCESS. dag_id=data_ingestion_gcs_dag, task_id=getData, execution_date=20221204T000000, start_date=20221205T112301, end_date=20221205T112302
[2022-12-05 11:23:02,283] {local_task_job.py:154} INFO - Task exited with return code 0
[2022-12-05 11:23:02,515] {local_task_job.py:264} INFO - 1 downstream tasks scheduled from follow-on schedule check
