[2022-12-04 07:15:12,781] {taskinstance.py:1032} INFO - Dependencies all met for <TaskInstance: data_ingestion_gcs_dag.download_dataset_task manual__2022-12-04T07:04:47.742537+00:00 [queued]>
[2022-12-04 07:15:12,800] {taskinstance.py:1032} INFO - Dependencies all met for <TaskInstance: data_ingestion_gcs_dag.download_dataset_task manual__2022-12-04T07:04:47.742537+00:00 [queued]>
[2022-12-04 07:15:12,801] {taskinstance.py:1238} INFO - 
--------------------------------------------------------------------------------
[2022-12-04 07:15:12,801] {taskinstance.py:1239} INFO - Starting attempt 2 of 2
[2022-12-04 07:15:12,801] {taskinstance.py:1240} INFO - 
--------------------------------------------------------------------------------
[2022-12-04 07:15:12,825] {taskinstance.py:1259} INFO - Executing <Task(BashOperator): download_dataset_task> on 2022-12-04 07:04:47.742537+00:00
[2022-12-04 07:15:12,834] {standard_task_runner.py:52} INFO - Started process 572 to run task
[2022-12-04 07:15:12,847] {standard_task_runner.py:76} INFO - Running: ['***', 'tasks', 'run', 'data_ingestion_gcs_dag', 'download_dataset_task', 'manual__2022-12-04T07:04:47.742537+00:00', '--job-id', '6', '--raw', '--subdir', 'DAGS_FOLDER/data_ingestion_gcs_dag.py', '--cfg-path', '/tmp/tmps2utntb5', '--error-file', '/tmp/tmpnnhb6di9']
[2022-12-04 07:15:12,849] {standard_task_runner.py:77} INFO - Job 6: Subtask download_dataset_task
[2022-12-04 07:15:12,948] {logging_mixin.py:109} INFO - Running <TaskInstance: data_ingestion_gcs_dag.download_dataset_task manual__2022-12-04T07:04:47.742537+00:00 [running]> on host b5c579fe1818
[2022-12-04 07:15:13,042] {taskinstance.py:1426} INFO - Exporting the following env vars:
AIRFLOW_CTX_DAG_OWNER=***
AIRFLOW_CTX_DAG_ID=data_ingestion_gcs_dag
AIRFLOW_CTX_TASK_ID=download_dataset_task
AIRFLOW_CTX_EXECUTION_DATE=2022-12-04T07:04:47.742537+00:00
AIRFLOW_CTX_DAG_RUN_ID=manual__2022-12-04T07:04:47.742537+00:00
[2022-12-04 07:15:13,044] {subprocess.py:62} INFO - Tmp dir root location: 
 /tmp
[2022-12-04 07:15:13,045] {subprocess.py:74} INFO - Running command: ['bash', '-c', 'curl -sSL https://d37c16vzurychx.cloudfront.net/misc/taxi+_zone_lookup.csv > /opt/***/taxi+_zone_lookup.csv']
[2022-12-04 07:15:13,068] {subprocess.py:85} INFO - Output:
[2022-12-04 07:15:13,132] {subprocess.py:89} INFO - curl: (6) Could not resolve host: d37c16vzurychx.cloudfront.net
[2022-12-04 07:15:13,133] {subprocess.py:93} INFO - Command exited with return code 6
[2022-12-04 07:15:13,158] {taskinstance.py:1700} ERROR - Task failed with exception
Traceback (most recent call last):
  File "/home/airflow/.local/lib/python3.7/site-packages/airflow/models/taskinstance.py", line 1329, in _run_raw_task
    self._execute_task_with_callbacks(context)
  File "/home/airflow/.local/lib/python3.7/site-packages/airflow/models/taskinstance.py", line 1455, in _execute_task_with_callbacks
    result = self._execute_task(context, self.task)
  File "/home/airflow/.local/lib/python3.7/site-packages/airflow/models/taskinstance.py", line 1511, in _execute_task
    result = execute_callable(context=context)
  File "/home/airflow/.local/lib/python3.7/site-packages/airflow/operators/bash.py", line 188, in execute
    f'Bash command failed. The command returned a non-zero exit code {result.exit_code}.'
airflow.exceptions.AirflowException: Bash command failed. The command returned a non-zero exit code 6.
[2022-12-04 07:15:13,170] {taskinstance.py:1277} INFO - Marking task as FAILED. dag_id=data_ingestion_gcs_dag, task_id=download_dataset_task, execution_date=20221204T070447, start_date=20221204T071512, end_date=20221204T071513
[2022-12-04 07:15:13,205] {standard_task_runner.py:92} ERROR - Failed to execute job 6 for task download_dataset_task
Traceback (most recent call last):
  File "/home/airflow/.local/lib/python3.7/site-packages/airflow/task/task_runner/standard_task_runner.py", line 85, in _start_by_fork
    args.func(args, dag=self.dag)
  File "/home/airflow/.local/lib/python3.7/site-packages/airflow/cli/cli_parser.py", line 48, in command
    return func(*args, **kwargs)
  File "/home/airflow/.local/lib/python3.7/site-packages/airflow/utils/cli.py", line 92, in wrapper
    return f(*args, **kwargs)
  File "/home/airflow/.local/lib/python3.7/site-packages/airflow/cli/commands/task_command.py", line 298, in task_run
    _run_task_by_selected_method(args, dag, ti)
  File "/home/airflow/.local/lib/python3.7/site-packages/airflow/cli/commands/task_command.py", line 107, in _run_task_by_selected_method
    _run_raw_task(args, ti)
  File "/home/airflow/.local/lib/python3.7/site-packages/airflow/cli/commands/task_command.py", line 184, in _run_raw_task
    error_file=args.error_file,
  File "/home/airflow/.local/lib/python3.7/site-packages/airflow/utils/session.py", line 70, in wrapper
    return func(*args, session=session, **kwargs)
  File "/home/airflow/.local/lib/python3.7/site-packages/airflow/models/taskinstance.py", line 1329, in _run_raw_task
    self._execute_task_with_callbacks(context)
  File "/home/airflow/.local/lib/python3.7/site-packages/airflow/models/taskinstance.py", line 1455, in _execute_task_with_callbacks
    result = self._execute_task(context, self.task)
  File "/home/airflow/.local/lib/python3.7/site-packages/airflow/models/taskinstance.py", line 1511, in _execute_task
    result = execute_callable(context=context)
  File "/home/airflow/.local/lib/python3.7/site-packages/airflow/operators/bash.py", line 188, in execute
    f'Bash command failed. The command returned a non-zero exit code {result.exit_code}.'
airflow.exceptions.AirflowException: Bash command failed. The command returned a non-zero exit code 6.
[2022-12-04 07:15:13,262] {local_task_job.py:154} INFO - Task exited with return code 1
[2022-12-04 07:15:13,337] {local_task_job.py:264} INFO - 0 downstream tasks scheduled from follow-on schedule check
