[2022-12-04 07:15:18,956] {taskinstance.py:1032} INFO - Dependencies all met for <TaskInstance: data_ingestion_gcs_dag.download_dataset_task scheduled__2022-12-03T00:00:00+00:00 [queued]>
[2022-12-04 07:15:18,999] {taskinstance.py:1032} INFO - Dependencies all met for <TaskInstance: data_ingestion_gcs_dag.download_dataset_task scheduled__2022-12-03T00:00:00+00:00 [queued]>
[2022-12-04 07:15:19,005] {taskinstance.py:1238} INFO - 
--------------------------------------------------------------------------------
[2022-12-04 07:15:19,005] {taskinstance.py:1239} INFO - Starting attempt 3 of 4
[2022-12-04 07:15:19,006] {taskinstance.py:1240} INFO - 
--------------------------------------------------------------------------------
[2022-12-04 07:15:19,054] {taskinstance.py:1259} INFO - Executing <Task(BashOperator): download_dataset_task> on 2022-12-03 00:00:00+00:00
[2022-12-04 07:15:19,083] {standard_task_runner.py:52} INFO - Started process 578 to run task
[2022-12-04 07:15:19,103] {standard_task_runner.py:76} INFO - Running: ['***', 'tasks', 'run', 'data_ingestion_gcs_dag', 'download_dataset_task', 'scheduled__2022-12-03T00:00:00+00:00', '--job-id', '7', '--raw', '--subdir', 'DAGS_FOLDER/data_ingestion_gcs_dag.py', '--cfg-path', '/tmp/tmp3y4xdtvu', '--error-file', '/tmp/tmpoo9phbls']
[2022-12-04 07:15:19,119] {standard_task_runner.py:77} INFO - Job 7: Subtask download_dataset_task
[2022-12-04 07:15:19,308] {logging_mixin.py:109} INFO - Running <TaskInstance: data_ingestion_gcs_dag.download_dataset_task scheduled__2022-12-03T00:00:00+00:00 [running]> on host b5c579fe1818
[2022-12-04 07:15:19,482] {taskinstance.py:1426} INFO - Exporting the following env vars:
AIRFLOW_CTX_DAG_OWNER=***
AIRFLOW_CTX_DAG_ID=data_ingestion_gcs_dag
AIRFLOW_CTX_TASK_ID=download_dataset_task
AIRFLOW_CTX_EXECUTION_DATE=2022-12-03T00:00:00+00:00
AIRFLOW_CTX_DAG_RUN_ID=scheduled__2022-12-03T00:00:00+00:00
[2022-12-04 07:15:19,484] {subprocess.py:62} INFO - Tmp dir root location: 
 /tmp
[2022-12-04 07:15:19,485] {subprocess.py:74} INFO - Running command: ['bash', '-c', 'curl -sSL https://d37c16vzurychx.cloudfront.net/misc/taxi+_zone_lookup.csv > /opt/***/taxi+_zone_lookup.csv']
[2022-12-04 07:15:19,539] {subprocess.py:85} INFO - Output:
[2022-12-04 07:15:19,599] {subprocess.py:89} INFO - curl: (6) Could not resolve host: d37c16vzurychx.cloudfront.net
[2022-12-04 07:15:19,602] {subprocess.py:93} INFO - Command exited with return code 6
[2022-12-04 07:15:19,652] {taskinstance.py:1700} ERROR - Task failed with exception
Traceback (most recent call last):
  File "/home/airflow/.local/lib/python3.7/site-packages/airflow/models/taskinstance.py", line 1329, in _run_raw_task
    self._execute_task_with_callbacks(context)
  File "/home/airflow/.local/lib/python3.7/site-packages/airflow/models/taskinstance.py", line 1455, in _execute_task_with_callbacks
    result = self._execute_task(context, self.task)
  File "/home/airflow/.local/lib/python3.7/site-packages/airflow/models/taskinstance.py", line 1511, in _execute_task
    result = execute_callable(context=context)
  File "/home/airflow/.local/lib/python3.7/site-packages/airflow/operators/bash.py", line 188, in execute
    f'Bash command failed. The command returned a non-zero exit code {result.exit_code}.'
airflow.exceptions.AirflowException: Bash command failed. The command returned a non-zero exit code 6.
[2022-12-04 07:15:19,680] {taskinstance.py:1277} INFO - Marking task as UP_FOR_RETRY. dag_id=data_ingestion_gcs_dag, task_id=download_dataset_task, execution_date=20221203T000000, start_date=20221204T071518, end_date=20221204T071519
[2022-12-04 07:15:19,727] {standard_task_runner.py:92} ERROR - Failed to execute job 7 for task download_dataset_task
Traceback (most recent call last):
  File "/home/airflow/.local/lib/python3.7/site-packages/airflow/task/task_runner/standard_task_runner.py", line 85, in _start_by_fork
    args.func(args, dag=self.dag)
  File "/home/airflow/.local/lib/python3.7/site-packages/airflow/cli/cli_parser.py", line 48, in command
    return func(*args, **kwargs)
  File "/home/airflow/.local/lib/python3.7/site-packages/airflow/utils/cli.py", line 92, in wrapper
    return f(*args, **kwargs)
  File "/home/airflow/.local/lib/python3.7/site-packages/airflow/cli/commands/task_command.py", line 298, in task_run
    _run_task_by_selected_method(args, dag, ti)
  File "/home/airflow/.local/lib/python3.7/site-packages/airflow/cli/commands/task_command.py", line 107, in _run_task_by_selected_method
    _run_raw_task(args, ti)
  File "/home/airflow/.local/lib/python3.7/site-packages/airflow/cli/commands/task_command.py", line 184, in _run_raw_task
    error_file=args.error_file,
  File "/home/airflow/.local/lib/python3.7/site-packages/airflow/utils/session.py", line 70, in wrapper
    return func(*args, session=session, **kwargs)
  File "/home/airflow/.local/lib/python3.7/site-packages/airflow/models/taskinstance.py", line 1329, in _run_raw_task
    self._execute_task_with_callbacks(context)
  File "/home/airflow/.local/lib/python3.7/site-packages/airflow/models/taskinstance.py", line 1455, in _execute_task_with_callbacks
    result = self._execute_task(context, self.task)
  File "/home/airflow/.local/lib/python3.7/site-packages/airflow/models/taskinstance.py", line 1511, in _execute_task
    result = execute_callable(context=context)
  File "/home/airflow/.local/lib/python3.7/site-packages/airflow/operators/bash.py", line 188, in execute
    f'Bash command failed. The command returned a non-zero exit code {result.exit_code}.'
airflow.exceptions.AirflowException: Bash command failed. The command returned a non-zero exit code 6.
[2022-12-04 07:15:19,773] {local_task_job.py:154} INFO - Task exited with return code 1
[2022-12-04 07:15:19,919] {local_task_job.py:264} INFO - 0 downstream tasks scheduled from follow-on schedule check
